<?xml version="1.0"?>
<robot xmlns:xacro="http://ros.org/wiki/xacro">
  <xacro:macro name="abb_irb6700_200_260" params="prefix">
    <xacro:include filename="$(find abb_resources)/urdf/common_materials.xacro"/>
    <xacro:include filename="$(find abb_irb6700_support)/urdf/irb6700_200_260.transmission.xacro"/>
    <xacro:include filename="$(find abb_irb6700_support)/urdf/irb6700_200_260.gazebo.xacro"/>


    <xacro:macro name="cylinder_inertial" params="radius length mass *origin">
      <inertial>
        <mass value="${mass}" />
        <xacro:insert_block name="origin" />
        <inertia ixx="${0.0833333 * mass * (3 * radius * radius + length * length)}" ixy="0.0" ixz="0.0"
        iyy="${0.0833333 * mass * (3 * radius * radius + length * length)}" iyz="0.0"
        izz="${0.5 * mass * radius * radius}" />
      </inertial>
    </xacro:macro>

    <!-- link list -->
    <link name="${prefix}actuator_link">
      <collision>
        <origin xyz="0 0 0" rpy="0 0 0" />
        <geometry>
          <box size="1 8 0.2"/>
        </geometry>
        <xacro:material_abb_yellow/>
      </collision>
      <xacro:cylinder_inertial radius="0.06" length="0.05" mass="10">
          <origin xyz="0.0 0.0 0.0" rpy="0 0 0" />
      </xacro:cylinder_inertial>
    </link>
    <link name="${prefix}base_link">
      <visual>
        <origin xyz="0 0 0" rpy="0 0 0" />
        <geometry>
          <mesh filename="package://abb_irb6700_support/meshes/irb6700/visual/base_link.stl" />
        </geometry>
        <xacro:material_abb_white/>
      </visual>
      <collision>
        <origin xyz="0 0 0" rpy="0 0 0" />
        <geometry>
          <mesh filename="package://abb_irb6700_support/meshes/irb6700/collision/base_link.stl" />
        </geometry>
        <xacro:material_abb_yellow/>
      </collision>
      <xacro:cylinder_inertial radius="0.06" length="0.05" mass="10">
          <origin xyz="0.0 0.0 0.0" rpy="0 0 0" />
      </xacro:cylinder_inertial>
    </link>
    <link name="${prefix}link_1">
      <visual>
        <origin xyz="0 0 0" rpy="0 0 0" />
        <geometry>
          <mesh filename="package://abb_irb6700_support/meshes/irb6700/visual/link_1.stl" />
        </geometry>
        <xacro:material_abb_white/>
      </visual>
      <collision>
        <origin xyz="0 0 0" rpy="0 0 0" />
        <geometry>
          <mesh filename="package://abb_irb6700_support/meshes/irb6700/collision/link_1.stl" />
        </geometry>
        <xacro:material_abb_yellow/>
      </collision>
    </link>
    <link name="${prefix}link_2">
      <visual>
        <origin xyz="0 0 0" rpy="0 0 0" />
        <geometry>
          <mesh filename="package://abb_irb6700_support/meshes/irb6700_200_260/visual/link_2.stl" />
        </geometry>
        <xacro:material_abb_white/>
      </visual>
      <collision>
        <origin xyz="0 0 0" rpy="0 0 0" />
        <geometry>
          <mesh filename="package://abb_irb6700_support/meshes/irb6700_200_260/collision/link_2.stl" />
        </geometry>
        <xacro:material_abb_yellow/>
      </collision>
    </link>
    <link name="${prefix}link_3">
      <visual>
        <origin xyz="0 0 0" rpy="0 0 0" />
        <geometry>
          <mesh filename="package://abb_irb6700_support/meshes/irb6700_200_260/visual/link_3.stl" />
        </geometry>
        <xacro:material_abb_white/>
      </visual>
      <collision>
        <origin xyz="0 0 0" rpy="0 0 0" />
        <geometry>
          <mesh filename="package://abb_irb6700_support/meshes/irb6700_200_260/collision/link_3.stl" />
        </geometry>
        <xacro:material_abb_yellow/>
      </collision>
    </link>
    <link name="${prefix}link_4">
      <visual>
        <origin xyz="0 0 0" rpy="0 0 0" />
        <geometry>
          <mesh filename="package://abb_irb6700_support/meshes/irb6700_200_260/visual/link_4.stl" />
        </geometry>
        <xacro:material_abb_white/>
      </visual>
      <collision>
        <origin xyz="0 0 0" rpy="0 0 0" />
        <geometry>
          <mesh filename="package://abb_irb6700_support/meshes/irb6700_200_260/collision/link_4.stl" />
        </geometry>
        <xacro:material_abb_yellow/>
      </collision>
    </link>
    <link name="${prefix}link_5">
      <visual>
        <origin xyz="0 0 0" rpy="0 0 0" />
        <geometry>
          <mesh filename="package://abb_irb6700_support/meshes/irb6700/visual/link_5.stl" />
        </geometry>
        <xacro:material_abb_white/>
      </visual>
      <collision>
        <origin xyz="0 0 0" rpy="0 0 0" />
        <geometry>
          <mesh filename="package://abb_irb6700_support/meshes/irb6700/collision/link_5.stl" />
        </geometry>
        <xacro:material_abb_yellow/>
      </collision>
    </link>
    <link name="${prefix}link_6">
      <visual>
        <origin xyz="0 0 0" rpy="0 0 0" />
        <geometry>
          <mesh filename="package://abb_irb6700_support/meshes/irb6700/visual/link_6.stl" />
        </geometry>
        <xacro:material_abb_white/>
      </visual>
      <collision>
        <origin xyz="0 0 0" rpy="0 0 0" />
        <geometry>
          <mesh filename="package://abb_irb6700_support/meshes/irb6700/collision/link_6.stl" />
        </geometry>
        <xacro:material_abb_yellow/>
      </collision>
    </link>

    <joint name="${prefix}actuator_joint" type="prismatic">
      <origin xyz="0 0 0" rpy="0 0 0" />
      <parent link="${prefix}actuator_link" />
      <child link="${prefix}base_link" />
      <axis xyz="0 1 0" />
      <limit lower="-4" upper="4" effort="0" velocity="1" />
    </joint>
    <joint name="${prefix}joint_1" type="revolute">
      <origin xyz="0 0 0.88" rpy="0 0 0" />
      <parent link="${prefix}base_link" />
      <child link="${prefix}link_1" />
      <axis xyz="0 0 1" />
      <limit lower="-${radians(170)}" upper="${radians(170)}" effort="0" velocity="${radians(110)}" />
    </joint>
    <joint name="${prefix}joint_2" type="revolute">
      <origin xyz="0.32 0 0" rpy="0 0 0" />
      <parent link="${prefix}link_1" />
      <child link="${prefix}link_2" />
      <axis xyz="0 1 0" />
      <limit lower="-${radians(65)}" upper="${radians(85)}" effort="0" velocity="${radians(110)}" />
    </joint>
    <joint name="${prefix}joint_3" type="revolute">
      <origin xyz="0 0 1.125" rpy="0 0 0" />
      <parent link="${prefix}link_2" />
      <child link="${prefix}link_3" />
      <axis xyz="0 1 0" />
      <limit lower="-${radians(180)}" upper="${radians(70)}" effort="0" velocity="${radians(110)}" />
    </joint>
    <joint name="${prefix}joint_4" type="revolute">
      <origin xyz="0 0 0.2" rpy="0 0 0" />
      <parent link="${prefix}link_3" />
      <child link="${prefix}link_4" />
      <axis xyz="1 0 0" />
      <limit lower="-${radians(300)}" upper="${radians(300)}" effort="0" velocity="${radians(190)}" />
    </joint>
    <joint name="${prefix}joint_5" type="revolute">
      <origin xyz="1.1425 0 0" rpy="0 0 0" />
      <parent link="${prefix}link_4" />
      <child link="${prefix}link_5" />
      <axis xyz="0 1 0" />
      <limit lower="-${radians(130)}" upper="${radians(130)}" effort="0" velocity="${radians(150)}" />
    </joint>
    <joint name="${prefix}joint_6" type="revolute">
      <origin xyz="0.2 0 0" rpy="0 0 0" />
      <parent link="${prefix}link_5" />
      <child link="${prefix}link_6" />
      <axis xyz="1 0 0" />
      <limit lower="-${radians(360)}" upper="${radians(360)}" effort="0" velocity="${radians(210)}" />
    </joint>

    <!-- ROS-Industrial 'base' frame: base_link to ABB World Coordinates transform -->
    <link name="${prefix}base" />
    <joint name="${prefix}base_link-base" type="fixed">
      <origin xyz="0 0 0" rpy="0 0 0"/>
      <parent link="${prefix}base_link"/>
      <child link="${prefix}base"/>
    </joint>

    <!-- ROS-Industrial 'flange' frame: attachment point for EEF models -->
    <link name="${prefix}flange"/>
    <joint type="fixed" name="${prefix}joint_6-flange">
      <origin xyz="0 0 0" rpy="0 0 0"/>
      <parent link="${prefix}link_6"/>
      <child link="${prefix}flange"/>
    </joint>

    <!-- ROS-Industrial 'tool0' frame: all-zeros tool frame -->
    <link name="${prefix}tool0" />
    <joint name="${prefix}link_6-tool0" type="fixed">
      <origin xyz="0 0 0" rpy="0 ${radians(90)} 0" />
      <parent link="${prefix}flange" />
      <child link="${prefix}tool0" />
    </joint>

    <xacro:irb6700_200_260_transmission prefix="${prefix}" />
    <xacro:irb6700_200_260_gazebo prefix="${prefix}" />
  </xacro:macro>
</robot>
